Workbook

Sheet Assumptions
A1: Particular (Rs. in Crores) | B1: 2017-18 | C1: 2018-19 | D1: 2019-20 | E1: 2020-21 | F1: 2021-22 | G1: 2022-23 | H1: 2023-24 | I1: 2024-25 | J1: 2025-26 | K1: 2026-27
B2: Audited | C2: Audited | D2: Audited | E2: Projected | F2: Projected | G2: Projected | H2: Projected | I2: Projected | J2: Projected | K2: Projected
A3: Growth in business | B3: =B4/702-1 -> 0.47008547 | C3: 0.5 | D3: =D4/C4-1 -> 0.41494528 | AV3: =(AV4-#REF!)/#REF! -> #REF!
A4: Business | B4: 1032 | C4: 1550.59 | D4: 2194 | E4: =ROUND(D4*(1+(-40%)),-1)-70 -> 1250 | F4: =ROUND(E4*(1+65%),-1) -> 2060 | G4: =ROUND(F4*(1+20%),-1) -> 2470 | H4: =ROUND(G4*(1+20%),-1) -> 2960 | I4: =ROUND(H4*(1+20%),-1) -> 3550 | J4: =ROUND(I4*(1+20%),-1) -> 4260 | K4: =ROUND(J4*(1+20%),-1) -> 5110 | AV4: 5600
A6: State | B6: 6 | C6: 6 | D6: 6 | E6: 6 | F6: 6 | G6: 6 | H6: 7 | I6: 8 | J6: 9 | K6: 10 | AV6: 5
A7: Branches | B7: 226 | C7: 262 | D7: 320 | E7: 330 | F7: 330 | G7: 350 | H7: 350 | I7: 350 | J7: 350 | K7: 350 | AV7: =ROUND(#REF!*(1+AV3/2),-1) -> #REF!
A8: Manpower | B8: 1850 | C8: 2563 | D8: 3600 | E8: =D8+500 -> 4100 | F8: 4000 | G8: =F8 -> 4000 | H8: =G8 -> 4000 | I8: =H8 -> 4000 | J8: =I8 -> 4000 | K8: =J8 -> 4000 | AV8: #REF!
A9: Average Tenor | B9: 42 | C9: 42 | D9: 42 | E9: =D9 -> 42 | F9: =E9 -> 42 | G9: =F9 -> 42 | H9: =G9 -> 42 | I9: =H9 -> 42 | J9: =I9 -> 42 | K9: =J9 -> 42 | AV9: =#REF! -> #REF!
A10: Precloser % | B10: 0 | C10: 0 | D10: 0 | E10: =D10 -> 0 | F10: =E10 -> 0 | G10: =F10 -> 0 | H10: =G10 -> 0 | I10: =H10 -> 0 | J10: =I10 -> 0 | K10: =J10 -> 0 | AV10: =#REF! -> #REF!
A11: Assigned assets as % of business | B11: 0.215 | C11: 0.135 | D11: 0.075 | E11: 0.1 | F11: 0.1 | G11: 0.1 | H11: 0.05 | I11: 0.1 | J11: 0.1 | K11: 0.1 | AV11: =#REF! -> #REF!
A12: Assignment | B12: =ROUND(B4*B11,-1) -> 220 | C12: =ROUND(C4*C11,-1) -> 210 | D12: =ROUND(D4*D11,-1) -> 160 | E12: =ROUND(E4*E11,-1) -> 130 | F12: =ROUND(F4*F11,-1) -> 210 | G12: =ROUND(G4*G11,-1) -> 250 | H12: =ROUND(H4*H11,-1) -> 150 | I12: =ROUND(I4*I11,-1) -> 360 | ... K12: =ROUND(K4*K11,-1) -> 510 | AV12: =ROUND(AV4*AV11,-1) -> #REF!
A13: Direct Assignment (50%) | C13: 0 | D13: =D12/2 -> 80 | E13: =E12/2 -> 65 | F13: =F12/2 -> 105 | G13: =G12/2 -> 125 | H13: =H12/2 -> 75 | I13: =I12/2 -> 180 | J13: =J12/2 -> 215 | K13: =K12/2 -> 255
A14: Assignment through PTC Strcuture balance (50%) | C14: 0 | D14: =D12-D13 -> 80 | E14: =E12-E13 -> 65 | F14: =F12-F13 -> 105 | G14: =G12-G13 -> 125 | H14: =H12-H13 -> 75 | I14: =I12-I13 -> 180 | J14: =J12-J13 -> 215 | K14: =K12-K13 -> 255
A15: Collections Against DA | C15: 0 | D15: =((D13/36)*3)+((C13/36*12)) -> 6.6666667 | E15: =((E13/36)*3)+((D13/36*12)) -> 32.083333 | F15: =((F13/36)*3)+((E13/36*12)) -> 30.416667 | G15: =((G13/36)*3)+((F13/36*12)) -> 45.416667 | H15: =((H13/36)*3)+((G13/36*12)) -> 47.916667 | I15: =((I13/36)*3)+((H13/36*12)) -> 40 | J15: =((J13/36)*3)+((I13/36*12)) -> 77.916667 | K15: =((K13/36)*3)+((J13/36*12)) -> 92.916667
A16: Run Down DA | C16: 0 | D16: =D13-D15 -> 73.333333 | E16: =E13-E15 -> 32.916667 | F16: =F13-F15 -> 74.583333 | G16: =G13-G15 -> 79.583333 | H16: =H13-H15 -> 27.083333 | I16: =I13-I15 -> 140 | J16: =J13-J15 -> 137.08333 | K16: =K13-K15 -> 162.08333
A17: Run Down PTC Pool | C17: 0 | D17: 54.988825 | E17: 149.39341 | F17: 205.17961 | G17: 290.4768 | H17: 314.25215 | I17: 356.58793 | J17: -137.08333 | K17: -162.08333
A18: AssiFnment Primum | B18: 0 | C18: 0 | D18: 0 | E18: 0 | F18: 0 | G18: 0 | H18: 0 | I18: 0 | J18: 0 | K18: 0 | AV18: 0
A19: Effective Assignment Rate | B19: 0.12 | C19: 0.11 | D19: 0.11 | E19: 0.11 | F19: =E19 -> 0.11 | G19: =F19 -> 0.11 | H19: =G19 -> 0.11 | I19: =H19 -> 0.11 | J19: =I19 -> 0.11 | K19: =J19 -> 0.11 | AV19: =#REF!-0.25% -> #REF!
A20: New FD for Assignment | B20: 0.0325 | C20: 0.025 | D20: =C20 -> 0.025 | E20: =D20 -> 0.025 | F20: =E20-0.0025 -> 0.0225 | G20: =F20-0.0025 -> 0.02 | H20: =G20-0.0025 -> 0.0175 | I20: =H20-0.0025 -> 0.015 | J20: =I20-0.0025 -> 0.0125 | K20: =J20-0.0025 -> 0.01 | AV20: =#REF!-0.0025 -> #REF!
A21: MMR for Assignment | B21: 0.07 | C21: 0.07 | D21: =C21 -> 0.07 | E21: =D21 -> 0.07 | F21: =E21 -> 0.07 | G21: =F21 -> 0.07 | H21: =G21 -> 0.07 | I21: =H21 -> 0.07 | J21: =I21 -> 0.07 | K21: =J21 -> 0.07 | AV21: =#REF! -> #REF!
A22: IRR | B22: 0.2125 | C22: =B22 -> 0.2125 | D22: 0.21 | E22: 0.1925 | F22: 0.19 | G22: =F22-0.25% -> 0.1875 | H22: =G22 -> 0.1875 | I22: =H22-0.25% -> 0.185 | J22: =I22 -> 0.185 | K22: =J22 -> 0.185 | AV22: =#REF!-0.15% -> #REF!
A23: Collection ratio | B23: 0.97 | C23: 0.97 | D23: =C23 -> 0.97 | E23: =D23 -> 0.97 | F23: =E23 -> 0.97 | G23: =F23 -> 0.97 | H23: =G23 -> 0.97 | I23: =H23 -> 0.97 | J23: =I23 -> 0.97 | K23: =J23 -> 0.97 | AV23: =#REF! -> #REF! | AW23: =#REF!-#REF! -> #REF!
A25: Additional Tire-I capital | B25: =B59 -> 0 | C25: =C59 -> 0 | D25: =D59 -> 235 | E25: =E59 -> 0 | F25: =F59 -> 0 | G25: =G59 -> 0 | H25: =H59 -> 150 | I25: =I59 -> 0 | ... K25: =K59 -> 0 | AV25: =AV59 -> 0
A26: Premum rate of Issue | B26: 11900 | C26: 0 | D26: 0 | E26: 0 | F26: 0 | G26: 0 | H26: 0 | I26: 0 | J26: 0 | K26: 0 | AV26: 0
A27: Additional Tire-II capital | B27: =B56 -> 0 | C27: =C56 -> 0 | D27: =D56 -> 0 | E27: =E56 -> 0 | F27: =F56 -> 0 | G27: =G56 -> 0 | H27: =H56 -> 0 | I27: =I56 -> 0 | ... K27: =K56 -> 0 | AV27: =AV56 -> 20
A28: Cost of Tire-II | B28: 0.125 | C28: 0.12 | D28: =C28-0.5% -> 0.115 | E28: =D28-0.5% -> 0.11 | F28: =E28+1.5% -> 0.125 | G28: =F28-0.5% -> 0.12 | H28: =G28-0% -> 0.12 | I28: =H28-0.5% -> 0.115 | J28: =I28-0% -> 0.115 | K28: =J28-0% -> 0.115 | AV28: =#REF!-0.5% -> #REF!
A29: New TL taken | B29: =Assumptions!B60 -> 0 | C29: =Assumptions!C60 -> 0 | D29: =Assumptions!D60 -> 1250 | E29: =Assumptions!E60 -> 950 | F29: =Assumptions!F60 -> 1200 | G29: =Assumptions!G60 -> 1350 | H29: =Assumptions!H60 -> 1850 | I29: =Assumptions!I60 -> 1950 | ... K29: =Assumptions!K60 -> 3000 | L29: 2800 | AV29: =Assumptions!AV60 -> 550
A30: FD for new TL | B30: 0 | C30: 0 | D30: 0 | E30: 0 | F30: 0 | G30: 0 | H30: 0 | I30: 0 | J30: 0 | K30: 0 | AV30: 0
A31: Rate on TL | B31: 0.11 | C31: 0.12 | D31: =C31 -> 0.12 | E31: =D31-0.25% -> 0.1175 | F31: =E31-0.25% -> 0.115 | G31: =F31-0.25% -> 0.1125 | H31: =G31-0.25% -> 0.11 | I31: =H31-0.25% -> 0.1075 | J31: =I31 -> 0.1075 | K31: =J31 -> 0.1075 | AV31: =#REF!-0.25% -> #REF!
A32: New CC taken | B32: =Assumptions!B58 -> 0 | C32: =Assumptions!C58 -> 0 | D32: =Assumptions!D58 -> 75 | E32: =Assumptions!E58 -> 0 | F32: =Assumptions!F58 -> 0 | G32: =Assumptions!G58 -> 0 | H32: =Assumptions!H58 -> 0 | I32: =Assumptions!I58 -> 0 | ... K32: =Assumptions!K58 -> 0 | AV32: =#REF!+5 -> #REF!
A33: Average rate on CC | B33: 0.11 | C33: 0.1 | D33: =C33-0.5% -> 0.095 | E33: 0.11 | F33: =E33-0.25% -> 0.1075 | G33: =F33-0.25% -> 0.105 | H33: =G33 -> 0.105 | I33: =H33 -> 0.105 | J33: =I33 -> 0.105 | K33: =J33 -> 0.105 | AV33: =#REF!-0.25% -> #REF!
A34: FD for new CC | B34: 0 | C34: 0 | D34: 0 | E34: 0 | F34: 0 | G34: 0 | H34: 0 | I34: 0 | J34: 0 | K34: 0 | AV34: 0
A35: Addition in FA | B35: =7-2.5 -> 4.5 | C35: 1 | D35: 2.5 | E35: 2.5 | F35: 2.5 | G35: 4.5 | H35: =G35+0.5 -> 5 | I35: =H35+0.5 -> 5.5 | J35: =I35+0.5 -> 6 | K35: =J35+0.5 -> 6.5 | AV35: 1
A36: % of GNPA | B36: 0.034999928 | C36: 0.035 | D36: 0.035 | E36: 0.035 | F36: 0.035 | G36: 0.035 | H36: 0.035 | I36: 0.035 | J36: 0.035 | K36: 0.035
A37: % of NNPA | B37: 0.017729254 | C37: 0.017161943 | D37: 0.020390668 | E37: 0.020390668 | F37: 0.020390668 | G37: 0.020181364 | H37: 0.019948106 | I37: 0.019837313 | J37: 0.020133814 | K37: 0.019825471
A39: GNPA Amount | B39: 35.36505 | C39: 53.539008 | D39: 103.19151 | E39: 109.12289 | F39: 130.32102 | G39: 155.95721 | H39: 64.277834 | I39: 90.1117 | J39: 109.45515 | K39: 109.45515
A40: NNPA | B40: =B39-'BS '!I36 -> 27.21285 | C40: =C39-'BS '!J36 -> 40.379999 | D40: 90.0325 | E40: =E39-'BS '!L36 -> 109.12289 | F40: =F39-'BS '!M36 -> 130.32102 | G40: =G39-'BS '!N36 -> 155.95721 | H40: 48.455598 | I40: 67.930359 | J40: 82.51234 | K40: 82.51234
A41: % of GNPA | B41: 0.035 | C41: 0.035 | D41: 0.035 | E41: 0.035 | F41: 0.035 | G41: 0.035 | H41: =C40-H40 -> -8.0755983 | I41: =D40-I40 -> 22.102141 | J41: =E40-J40 -> 26.610546 | K41: =F40-K40 -> 47.80868
A42: % of NNPA | B42: 0.027151006 | C42: 0.026626629 | D42: 0.030673694 | E42: 0.035 | F42: 0.035 | G42: 0.035
A44: Cash Bal | B44: ='BS '!I50 -> 9.1876765 | C44: ='BS '!J50 -> 74.275138 | D44: ='BS '!K50 -> 62.371605 | E44: ='BS '!L50 -> 244.25973 | F44: ='BS '!M50 -> 357.8814 | G44: ='BS '!N50 -> 324.64497 | H44: ='BS '!O50 -> 367.44907 | I44: ='BS '!P50 -> 472.65406 | ... K44: ='BS '!R50 -> 511.3476
...

Sheet BS 
B2: Ess Kay Fincorp Limited
B3: (Formerly Know as Ess Kay Auto Finance Private Limited)
C5: =ROUND(C42-C73,2) -> -0.01 | D5: =ROUND(D42-D73,2) -> 0 | E5: =+E42-E73 -> 0 | F5: =ROUND(F42-F73,2) -> 0 | G5: =ROUND(G42-G73,2) -> 0 | H5: =ROUND(H42-H73,2) -> 0 | I5: =ROUND(I42-I73,2) -> 0 | J5: =ROUND(J42-J73,2) -> 0 | K5: =ROUND(K42-K73,2) -> 0 | L5: =ROUND(L42-L73,2) -> 0 | M5: =ROUND(M42-M73,2) -> 0 | ... R5: =ROUND(R42-R73,2) -> 0
B6: Balance Sheet | R6: Rs. in crores
A7: Sr. | B7: Particulars | C7: 2012-13 | D7: 2013-14 | E7: 2014-15 | F7: 2015-16 | G7: 2016-17 | H7: 2017-18 | I7: =Assumptions!B1 -> 2017-18 | J7: =Assumptions!C1 -> 2018-19 | K7: 2019-20 | L7: =Assumptions!E1 -> 2020-21 | M7: =Assumptions!F1 -> 2021-22 | N7: =Assumptions!G1 -> 2022-23 | O7: =Assumptions!H1 -> 2023-24 | P7: =Assumptions!I1 -> 2024-25 | Q7: =Assumptions!J1 -> 2025-26 | R7: =Assumptions!K1 -> 2026-27
C8: Audited | D8: Audited | E8: Audited | F8: Audited | G8: Audited | H8: 43100 | I8: =Assumptions!B2 -> Audited | J8: =Assumptions!C2 -> Audited | K8: Audited | L8: =Assumptions!E2 -> Projected | M8: =Assumptions!F2 -> Projected | N8: =Assumptions!G2 -> Projected | O8: =Assumptions!H2 -> Projected | P8: =Assumptions!I2 -> Projected | Q8: =Assumptions!J2 -> Projected | R8: =Assumptions!K2 -> Projected
A9: A. | B9: Liabilities
A10: a.
A11: 1 | B11: Share Capital | C11: =(SUM(C12:C13)) -> 3.19458 | D11: =(SUM(D12:D13)) -> 3.22355 | E11: =SUM(E12:E13) -> 3.22355 | F11: =(SUM(F12:F13)) -> 3.22355 | G11: =(SUM(G12:G13)) -> 2.70709 | H11: =(SUM(H12:H13)) -> 3.50919 | I11: =(SUM(I12:I13)) -> 3.50919 | J11: =(SUM(J12:J13)) -> 4.6032258 | K11: =(SUM(K12:K13)) -> 5.039 | L11: =(SUM(L12:L13)) -> 5.039 | M11: =(SUM(M12:M13)) -> 5.039 | ... R11: =(SUM(R12:R13)) -> 155.039
A12: 1.a | B12: Equity Capital | C12: 1.99518 | D12: 2.02415 | E12: 2.02415 | F12: 2.02415 | G12: 2.70709 | H12: 3.50919 | I12: 3.50919 | J12: 4.6032258 | K12: 5.039 | L12: =K12+Assumptions!E25/(Assumptions!E26+100)*100 -> 5.039 | M12: =L12+Assumptions!F25/(Assumptions!F26+100)*100 -> 5.039 | N12: =M12+(Assumptions!G25/(Assumptions!G26+100)*100) -> 5.039 | O12: =N12+(Assumptions!H25/(Assumptions!H26+100)*100) -> 155.039 | P12: =O12+(Assumptions!I25/(Assumptions!I26+100)*100) -> 155.039 | Q12: =P12+(Assumptions!J25/(Assumptions!J26+100)*100) -> 155.039 | R12: =Q12+(Assumptions!K25/(Assumptions!K26+100)*100) -> 155.039
A13: 1.b | B13: Prefrence Capital | C13: 1.1994 | D13: 1.1994 | E13: 1.1994 | F13: 1.1994 | G13: 0 | I13: =G13 -> 0 | J13: 0 | K13: 0 | L13: 0 | M13: 0 | N13: 0 | O13: 0 | P13: 0 | Q13: 0 | R13: 0
A14: 2 | B14: Reserves & Surplus | C14: =ROUND(SUM(C15:C18),2) -> 41.75 | D14: =(SUM(D15:D18)) -> 49.717124 | E14: =(SUM(E15:E18)) -> 58.738461 | F14: =SUM(F15:F18) -> 70.749227 | G14: =ROUND(SUM(G15:G18),2) -> 83.56 | H14: =ROUND(SUM(H15:H18),2) -> 192.8 | I14: =ROUND(SUM(I15:I18),2) -> 202.79 | J14: =SUM(J15:J18) -> 550.5814 | K14: =SUM(K15:K18) -> 873.6885 | L14: =ROUND(SUM(L15:L18),2) -> 963.66 | M14: =ROUND(SUM(M15:M18),2) -> 1093.19 | N14: =ROUND(SUM(N15:N18),2) -> 1258.41 | O14: =ROUND(SUM(O15:O18),2) -> 1467.86 | P14: =ROUND(SUM(P15:P18),2) -> 1730.18 | Q14: =ROUND(SUM(Q15:Q18),2) -> 2041.19 | R14: =ROUND(SUM(R15:R18),2) -> 2421.61
A15: 2.a | B15: Profit and Loss Account | C15: 13.731394 | D15: =C15+('P&L'!D34-'BS '!D17+C17) -> 20.130757 | E15: 27.343088 | F15: 36.951672 | G15: 46.790375 | H15: 54.8185 | I15: =G15+('P&L'!I34-'BS '!I17+G17) -> 64.35216 | J15: 106.13632 | K15: 176.35636 | L15: =K15+('P&L'!L34*80%) -> 248.32957 | M15: =L15+('P&L'!M34-'BS '!M17+L17) -> 351.95816 | N15: =M15+('P&L'!N34-'BS '!N17+M17) -> 484.13731 | O15: =N15+('P&L'!O34-'BS '!O17+N17) -> 651.69221 | P15: =O15+('P&L'!P34-'BS '!P17+O17) -> 861.5461 | Q15: =P15+('P&L'!Q34-'BS '!Q17+P17) -> 1110.3569 | R15: =Q15+('P&L'!R34-'BS '!R17+Q17) -> 1414.693
A16: 2.b | B16: Share Premium A/c | C16: 23.82872 | D16: 24.56224 | E16: 24.56224 | F16: 24.56224 | G16: 25.0787 | H16: 124.27649 | I16: 122.35398 | J16: 417.91357 | K16: 652.4778 | L16: =K16 -> 652.4778 | M16: =L16+(Assumptions!F25/(Assumptions!F26+100)*Assumptions!F26) -> 652.4778 | N16: =M16+(Assumptions!G25/(Assumptions!G26+100)*Assumptions!G26) -> 652.4778 | O16: =N16+(Assumptions!H25/(Assumptions!H26+100)*Assumptions!H26) -> 652.4778 | P16: =O16+(Assumptions!I25/(Assumptions!I26+100)*Assumptions!I26) -> 652.4778 | Q16: =P16+(Assumptions!J25/(Assumptions!J26+100)*Assumptions!J26) -> 652.4778 | R16: =Q16+(Assumptions!K25/(Assumptions!K26+100)*Assumptions!K26) -> 652.4778
A17: 2.c | B17: Statutory Reserve | C17: 3.4234894 | D17: 5.0241267 | E17: 6.8331323 | F17: 9.2353146 | G17: 11.695027 | H17: 13.702058 | I17: 16.085473 | J17: 26.531512 | K17: 44.85434 | L17: =K17+('P&L'!L34*0.2) -> 62.847642 | M17: =L17+('P&L'!M34*0.2) -> 88.75479 | N17: =M17+('P&L'!N34*0.2) -> 121.79958 | O17: =N17+('P&L'!O34*0.2) -> 163.6883 | P17: =O17+('P&L'!P34*0.2) -> 216.15177 | Q17: =P17+('P&L'!Q34*0.2) -> 278.35447 | R17: =Q17+('P&L'!R34*0.2) -> 354.43849
A18: 2.d | B18: Share Application Money | C18: 0.7625 | D18: 0 | E18: 0 | F18: 0 | G18: 0 | I18: 0 | J18: 0 | L18: 0 | M18: 0 | N18: 0 | O18: 0 | P18: 0 | Q18: 0 | R18: 0
B19: Net Worth | C19: =C14+C11 -> 44.94458 | D19: =D14+D11 -> 52.940674 | E19: =E14+E11 -> 61.962011 | F19: =F14+F11 -> 73.972777 | G19: =G14+G11 -> 86.26709 | H19: =H14+H11 -> 196.30919 | I19: =I14+I11 -> 206.29919 | J19: =J14+J11 -> 555.18462 | ... R19: =R14+R11 -> 2576.649
A20: b. | B20: Non Current Liabilities
A21: 3 | B21: Tier II Capital | C21: 16.5 | D21: 16.5 | E21: 16.5 | F21: 36.5 | G21: 40 | H21: 40 | I21: 40 | J21: 40 | K21: 40 | L21: 40 | M21: 20 | N21: 0 | O21: 0 | P21: 0 | Q21: 0 | R21: 0
A22: 4 | B22: Other Unsecured Loans | C22: 0 | D22: 0 | E22: 0 | F22: 50 | G22: 44.59 | H22: 76.9375 | I22: 45 | J22: 45 | K22: 45 | L22: 20 | M22: 20 | N22: 0 | O22: 0 | P22: 0 | Q22: 0 | R22: 0
A23: 5 | B23: T/L payable after 1 yr. | C23: 20.47732 | D23: 131.61432 | E23: 132.70853 | F23: 139.64692 | G23: 217.38131 | H23: 397.53845 | I23: 343.15158 | J23: 717.61793 | K23: =1242.72714950691+200+78.75+50+27.5 -> 1598.9771 | L23: 1504.0074 | M23: 1889.8902 | N23: 2062.8243 | O23: 2181.6035 | P23: 2083.2701 | Q23: 2795.4924 | R23: 3368.8257
A24: 6 | B24: Provisions of Standard Assets | C24: 0.5496619 | D24: 0.4622791 | E24: 0.458432 | F24: 0.6928468 | G24: 1.1702988 | H24: 2.14987 | I24: 2.4454213 | J24: 3.6942156 | K24: 48.8108 | L24: 52.902239 | M24: 69.685081 | N24: 78.560047 | O24: 91.416038 | P24: 98.046947 | Q24: 107.43281 | R24: 119.29551
B25: Provisions for NPA | J25: 1.5461111 | K25: 43.6747 | L25: 73.00495 | M25: 81.335356 | N25: 91.083313 | O25: 103.31384 | P25: 111.78126 | Q25: 122.40764 | R25: 135.43131
A26: 7 | B26: Other Long Term Provision | C26: 0.2954186 | D26: 0.6997856 | E26: 0.8313393 | F26: 1.2951595 | G26: 1.8620948 | H26: 2.1310815 | I26: 3.1273996 | J26: 5.007678 | K26: 6.0611597 | L26: =K26*1.1 -> 6.6672757 | M26: =L26*1.1 -> 7.3340032 | N26: =M26*1.1 -> 8.0674036 | O26: =N26*1.1 -> 8.8741439 | P26: =O26*1.1 -> 9.7615583 | Q26: =P26*1.1 -> 10.737714 | R26: =Q26*1.1 -> 11.811486
A27: 8 | B27: Other long Term liability | C27: 0 | D27: 0.767503 | E27: 0.9714065 | F27: 0.5051377 | G27: 6.1389357 | H27: 8.3835354 | I27: 11.532882 | J27: 31.404576 | K27: 24.462542 | L27: =K27*1.1 -> 26.908797 | M27: =L27*1.1 -> 29.599676 | N27: =M27*1.1 -> 32.559644 | O27: =N27*1.1 -> 35.815608 | P27: =O27*1.1 -> 39.397169 | Q27: =P27*1.1 -> 43.336886 | R27: =Q27*1.1 -> 47.670575
B28: Total Non Current Liabilities | C28: =SUM(C21:C27) -> 37.8224 | D28: =SUM(D21:D27) -> 150.04389 | E28: =SUM(E21:E27) -> 151.46971 | F28: =SUM(F21:F27) -> 228.64007 | G28: =SUM(G21:G27) -> 311.14264 | H28: =SUM(H21:H27) -> 527.14044 | I28: =SUM(I21:I27) -> 445.25729 | J28: =SUM(J21:J27) -> 844.27051 | ... R28: =SUM(R21:R27) -> 3683.0346
A29: 9 | B29: T/L payable within 1 yr. | C29: 11.185075 | D29: 71.634338 | E29: 131.17899 | F29: 121.90855 | G29: =266.67-G30 -> 250.17 | H29: 192.21563 | I29: 384.25001 | J29: 431.50367 | K29: =1167.97166186109-200-78.75-50-27.5 -> 811.72166 | L29: 845.58871 | M29: 834.11722 | N29: 1197.0659 | O29: 1731.2208 | P29: 2048.3333 | Q29: 2087.7778 | R29: 2426.6667
B30: Tier II Capital | C30: 0 | D30: 0 | E30: 0 | F30: 0 | G30: 16.5 | I30: 0 | J30: 0 | L30: 0 | M30: 0 | N30: 0 | O30: 0 | P30: 0 | Q30: 0 | R30: 0
A31: 10 | B31: Cash Credit limit / WCDL | C31: 51.260623 | D31: 14.208404 | E31: 16.503925 | F31: 73.308273 | G31: 45.971704 | H31: 139.07684 | I31: 85.230726 | J31: 65.046729 | K31: 66.081389 | L31: 122.85 | M31: 122.85 | N31: 122.85 | O31: 122.85 | P31: 122.85 | Q31: 122.85 | R31: 122.85
A32: =A31+1 -> 11 | B32: Other Short Term borrowing | I32: 0 | J32: 0
A33: 12 | B33: Other advances | C33: 40.044053 | D33: 1.3321822 | E33: 1.1777946 | F33: 1.5063084 | G33: 2.109709 | H33: 2.8054771 | I33: 5.9202471 | J33: 8.0400489 | L33: =K33*1.05 -> 0 | M33: =L33*1.05 -> 0 | N33: =M33*1.05 -> 0 | O33: =N33*1.05 -> 0 | P33: =O33*1.05 -> 0 | Q33: =P33*1.05 -> 0 | R33: =Q33*1.05 -> 0
A34: 13 | B34: Statutory Liabilities | C34: 0.6233723 | D34: 0.9610191 | E34: 0.5546346 | F34: 1.1442695 | G34: 1.3022109 | H34: 0.8007041 | I34: 2.228615 | J34: 3.3694038 | K34: =349.84/100 -> 3.4984 | L34: =K34*1.05 -> 3.67332 | M34: =L34*1.05 -> 3.856986 | N34: =M34*1.05 -> 4.0498353 | O34: =N34*1.05 -> 4.2523271 | P34: =O34*1.05 -> 4.4649434 | Q34: =P34*1.05 -> 4.6881906 | R34: =Q34*1.05 -> 4.9226001
A35: 14 | B35: Other current Liabilities | C35: 14.313544 | D35: 20.73392 | E35: 20.617776 | F35: 21.159944 | G35: =(3227915025/10^7)-G33-G34-(2666689019/10^7) -> 52.710681 | H35: 61.367088 | I35: 75.921036 | J35: 66.075088 | K35: 47.554362 | L35: =K35*1.5 -> 71.331544 | M35: =L35*1.05 -> 74.898121 | N35: =M35*1.05 -> 78.643027 | O35: =N35*1.05 -> 82.575178 | P35: =O35*1.05 -> 86.703937 | Q35: =P35*1.05 -> 91.039134 | R35: =Q35*1.05 -> 95.591091
A36: 15 | B36: Provisions for NPA | C36: 0.2074794 | D36: 0.38236138 | E36: 1.5797656 | F36: 1.8836108 | G36: 4.6769839 | H36: 12.710348 | I36: 8.1521998 | J36: 13.159008 | L36: 0 | M36: 0 | N36: 0 | O36: 0 | P36: 0 | Q36: 0 | R36: 0
A37: 16 | B37: Provisions for Standard assets (short term) | C37: 0.419391 | D37: 0.4895148 | E37: 0.7788724 | F37: 1.3790936 | G37: 0.8948392 | H37: 1.1026231 | I37: 1.4600044 | J37: 2.1901324 | K37: 25.1092 | L37: 31.363331 | M37: 41.313115 | N37: 46.574679 | O37: 54.196411 | P37: 58.127575 | Q37: 63.692026 | R37: 70.724885
A38: 17 | B38: Provision for Tax | C38: 0.3786103 | D38: 0.6181923 | E38: 0.1771806 | F38: 0 | G38: 2.4306141 | H38: 0.6591386 | I38: 3.4184613 | J38: 0.0615342 | K38: =301.68/100 -> 3.0168 | L38: 0 | M38: 0 | N38: 0 | O38: 0 | P38: 0 | Q38: 0 | R38: 0
A39: 18 | B39: Provision for Employee Benefit | C39: 0.1004647 | D39: 0.2043904 | E39: 0.2043904 | F39: 0.2754183 | G39: 0.2627288 | H39: 0.2627288 | I39: 0.4621841 | J39: 1.5779406 | L39: =K39*1.1 -> 0 | M39: =L39*1.1 -> 0 | N39: =M39*1.1 -> 0 | O39: =N39*1.1 -> 0 | P39: =O39*1.1 -> 0 | Q39: =P39*1.1 -> 0 | R39: =Q39*1.1 -> 0
A40: 19 | B40: Other Provisions (Short term) | C40: 0.2221139 | D40: 1.1634164 | E40: 0.2966733 | F40: 0 | G40: 1.0775995 | H40: 2.985249 | I40: 2.4005346 | J40: 2.6711314 | K40: 1.3391403 | L40: 13.261083 | M40: 14.774271 | N40: 16.544952 | O40: 18.766583 | P40: 20.304658 | Q40: 22.234901 | R40: 24.600605
B41: Current Liabilities | C41: =SUM(C29:C40) -> 118.75473 | D41: =SUM(D29:D40) -> 111.72774 | E41: =SUM(E29:E40) -> 173.07001 | F41: =SUM(F29:F40) -> 222.56547 | G41: =SUM(G29:G40) -> 378.10707 | H41: =SUM(H29:H40) -> 413.98583 | I41: =SUM(I29:I40) -> 569.44402 | J41: =SUM(J29:J40) -> 593.69469 | ... R41: =SUM(R29:R40) -> 2745.3558
B42: Total Liabilities | C42: =C41+C19+C28 -> 201.52171 | D42: =D41+D19+D28 -> 314.7123 | E42: =E41+E19+E28 -> 386.50173 | F42: =F41+F19+F28 -> 525.17831 | G42: =G41+G19+G28 -> 775.5168 | H42: =H41+H19+H28 -> 1137.4355 | I42: =I41+I19+I28 -> 1221.0005 | J42: =J41+J19+J28 -> 1993.1498 | ... R42: =R41+R19+R28 -> 9005.0394
...

Sheet Cash Flow
K1: Rs. in Crore
A2: Particulars | C2: =+'BS '!J7 -> 2018-19 | D2: =+'BS '!K7 -> 2019-20 | E2: =+'BS '!L7 -> 2020-21 | F2: =+'BS '!M7 -> 2021-22 | G2: =+'BS '!N7 -> 2022-23 | H2: =+'BS '!O7 -> 2023-24 | I2: =+'BS '!P7 -> 2024-25 | J2: =+'BS '!Q7 -> 2025-26 | K2: =+'BS '!R7 -> 2026-27
C3: Audited | D3: Audited | E3: Projected | F3: Projected | G3: Projected | H3: Projected | I3: Projected | J3: Projected | K3: Projected
A4: CASH FLOW ARISING FROM OPERATING ACTIVITIES:
A5: NET PROFIT BRFORE TAX AS PER P&L A/C | C5: =+'P&L'!J30 -> 75.491033 | D5: =+'P&L'!K30 -> 105.50468 | E5: =+'P&L'!L30 -> 120.22786 | F5: =+'P&L'!M30 -> 173.1067 | G5: =+'P&L'!N30 -> 220.79906 | H5: =+'P&L'!O30 -> 279.89259 | I5: =+'P&L'!P30 -> 350.55106 | J5: =+'P&L'!Q30 -> 415.62675 | K5: =+'P&L'!R30 -> 508.37908
A6: ADJUSTMENT FOR:
A7: Depreciation and Amortisation | C7: =+'P&L'!J24 -> 3.2124975 | D7: =+'P&L'!K24 -> 8.1753 | E7: =+'P&L'!L24 -> 8.2855814 | F7: =+'P&L'!M24 -> 8.6105814 | G7: =+'P&L'!N24 -> 9.1955814 | H7: =+'P&L'!O24 -> 9.8455814 | I7: =+'P&L'!P24 -> 10.560581 | J7: =+'P&L'!Q24 -> 11.340581 | K7: =+'P&L'!R24 -> 12.185581
A8: Provisions on Advances | C8: =+('BS '!J24+'BS '!J25+'BS '!J37)-('BS '!I24+'BS '!I25+'BS '!I37) -> 3.5250334 | D8: =+('BS '!K24+'BS '!K25+'BS '!K37)-('BS '!J24+'BS '!J25+'BS '!J37) -> 110.16424 | E8: =+('BS '!L24+'BS '!L25+'BS '!L37)-('BS '!K24+'BS '!K25+'BS '!K37) -> 39.67582 | F8: =+('BS '!M24+'BS '!M25+'BS '!M37)-('BS '!L24+'BS '!L25+'BS '!L37) -> 35.063032 | G8: =+('BS '!N24+'BS '!N25+'BS '!N37)-('BS '!M24+'BS '!M25+'BS '!M37) -> 23.884487 | H8: =+('BS '!O24+'BS '!O25+'BS '!O37)-('BS '!N24+'BS '!N25+'BS '!N37) -> 32.708253 | I8: =+('BS '!P24+'BS '!P25+'BS '!P37)-('BS '!O24+'BS '!O25+'BS '!O37) -> 19.029488 | J8: =+('BS '!Q24+'BS '!Q25+'BS '!Q37)-('BS '!P24+'BS '!P25+'BS '!P37) -> 25.57669 | K8: =+('BS '!R24+'BS '!R25+'BS '!R37)-('BS '!Q24+'BS '!Q25+'BS '!Q37) -> 31.919244
A9: Loss on Sale of Fixed Assets
A10: Provision for employee benefits | C10: =+'BS '!J39-'BS '!I39 -> 1.1157565 | D10: =+'BS '!K39-'BS '!J39 -> -1.5779406 | E10: =+'BS '!L39-'BS '!K39 -> 0 | F10: =+'BS '!M39-'BS '!L39 -> 0 | G10: =+'BS '!N39-'BS '!M39 -> 0 | H10: =+'BS '!O39-'BS '!N39 -> 0 | I10: =+'BS '!P39-'BS '!O39 -> 0 | J10: =+'BS '!Q39-'BS '!P39 -> 0 | K10: =+'BS '!R39-'BS '!Q39 -> 0
A12: Operating Profit before working capital Changes | C12: =SUM(C5:C11) -> 83.344321 | D12: =SUM(D5:D11) -> 222.26628 | E12: =SUM(E5:E11) -> 168.18926 | F12: =SUM(F5:F11) -> 216.78031 | G12: =SUM(G5:G11) -> 253.87913 | H12: =SUM(H5:H11) -> 322.44643 | I12: =SUM(I5:I11) -> 380.14113 | J12: =SUM(J5:J11) -> 452.54402 | K12: =SUM(K5:K11) -> 552.48391
A14: ADJUSTMENT FOR CHANGES IN WORKING CAPITAL
A15: (Increase)/ Decrease in Current Assets Loans advances | C15: =-SUM('BS '!J53:J58)+SUM('BS '!I53:I58) -> -188.66468 | D15: =-SUM('BS '!K53:K58)+SUM('BS '!J53:J58) -> -469.56189 | E15: =-SUM('BS '!L53:L58)+SUM('BS '!K53:K58) -> -35.861331 | F15: =-SUM('BS '!M53:M58)+SUM('BS '!L53:L58) -> -80.982526 | G15: =-SUM('BS '!N53:N58)+SUM('BS '!M53:M58) -> -460.74152 | H15: =-SUM('BS '!O53:O58)+SUM('BS '!N53:N58) -> -672.16053 | I15: =-SUM('BS '!P53:P58)+SUM('BS '!O53:O58) -> -468.81404 | J15: =-SUM('BS '!Q53:Q58)+SUM('BS '!P53:P58) -> -504.05348 | K15: =-SUM('BS '!R53:R58)+SUM('BS '!Q53:Q58) -> -627.26203
A16: (Increase)/ Decrease in Non Current Assets Loans advances | C16: =-SUM('BS '!J61:J64,'BS '!J66:J68,'BS '!J70)+SUM('BS '!I61:I64,'BS '!I66:I68,'BS '!I70) -> -327.0551 | D16: =-SUM('BS '!K61:K64,'BS '!K66:K68,'BS '!K70)+SUM('BS '!J61:J64,'BS '!J66:J68,'BS '!J70) -> -1012.0728 | E16: =-SUM('BS '!L61:L64,'BS '!L66:L68,'BS '!L70)+SUM('BS '!K61:K64,'BS '!K66:K68,'BS '!K70) -> -51.243204 | F16: =-SUM('BS '!M61:M64,'BS '!M66:M68,'BS '!M70)+SUM('BS '!L61:L64,'BS '!L66:L68,'BS '!L70) -> -519.33011 | G16: =-SUM('BS '!N61:N64,'BS '!N66:N68,'BS '!N70)+SUM('BS '!M61:M64,'BS '!M66:M68,'BS '!M70) -> -279.95066 | H16: =-SUM('BS '!O61:O64,'BS '!O66:O68,'BS '!O70)+SUM('BS '!N61:N64,'BS '!N66:N68,'BS '!N70) -> -397.67993 | I16: =-SUM('BS '!P61:P64,'BS '!P66:P68,'BS '!P70)+SUM('BS '!O61:O64,'BS '!O66:O68,'BS '!O70) -> 57.136101 | J16: =-SUM('BS '!Q61:Q64,'BS '!Q66:Q68,'BS '!Q70)+SUM('BS '!P61:P64,'BS '!P66:P68,'BS '!P70) -> -569.78113 | K16: =-SUM('BS '!R61:R64,'BS '!R66:R68,'BS '!R70)+SUM('BS '!Q61:Q64,'BS '!Q66:Q68,'BS '!Q70) -> -709.02384
A17: Increase/ (Decrease) in Current Liabilities | C17: =SUM('BS '!J26,'BS '!J33:J36,'BS '!J40)-SUM('BS '!I26,'BS '!I33:I36,'BS '!I40) -> 0.57232582 | D17: =SUM('BS '!K26,'BS '!K33:K36,'BS '!K40)-SUM('BS '!J26,'BS '!J33:J36,'BS '!J40) -> -39.869296 | E17: =SUM('BS '!L26,'BS '!L33:L36,'BS '!L40)-SUM('BS '!K26,'BS '!K33:K36,'BS '!K40) -> 36.48016 | F17: =SUM('BS '!M26,'BS '!M33:M36,'BS '!M40)-SUM('BS '!L26,'BS '!L33:L36,'BS '!L40) -> 5.9301587 | G17: =SUM('BS '!N26,'BS '!N33:N36,'BS '!N40)-SUM('BS '!M26,'BS '!M33:M36,'BS '!M40) -> 6.4418366 | H17: =SUM('BS '!O26,'BS '!O33:O36,'BS '!O40)-SUM('BS '!N26,'BS '!N33:N36,'BS '!N40) -> 7.1630147 | I17: =SUM('BS '!P26,'BS '!P33:P36,'BS '!P40)-SUM('BS '!O26,'BS '!O33:O36,'BS '!O40) -> 6.7668647 | J17: =SUM('BS '!Q26,'BS '!Q33:Q36,'BS '!Q40)-SUM('BS '!P26,'BS '!P33:P36,'BS '!P40) -> 7.4648428 | K17: =SUM('BS '!R26,'BS '!R33:R36,'BS '!R40)-SUM('BS '!Q26,'BS '!Q33:Q36,'BS '!Q40) -> 8.2258412
A18: Net Taxes Paid | C18: =+('BS '!J38-'BS '!I38)-SUM('P&L'!J31:J32) -> -26.617763 | D18: =+('BS '!K38-'BS '!J38)-SUM('P&L'!K31:K32) -> -24.012734 | E18: =+('BS '!L38-'BS '!K38)-SUM('P&L'!L31:L32) -> -33.278153 | F18: =+('BS '!M38-'BS '!L38)-SUM('P&L'!M31:M32) -> -43.570955 | G18: =+('BS '!N38-'BS '!M38)-SUM('P&L'!N31:N32) -> -55.575123 | H18: =+('BS '!O38-'BS '!N38)-SUM('P&L'!O31:O32) -> -70.448965 | I18: =+('BS '!P38-'BS '!O38)-SUM('P&L'!P31:P32) -> -88.233702 | J18: =+('BS '!Q38-'BS '!P38)-SUM('P&L'!Q31:Q32) -> -104.61325 | K18: =+('BS '!R38-'BS '!Q38)-SUM('P&L'!R31:R32) -> -127.95902
A20: Net Cash Flows from Operating activities (A) | C20: =+SUM(C12:C18) -> -458.4209 | D20: =+SUM(D12:D18) -> -1323.2504 | E20: =+SUM(E12:E18) -> 84.286736 | F20: =+SUM(F12:F18) -> -421.17313 | G20: =+SUM(G12:G18) -> -535.94634 | H20: =+SUM(H12:H18) -> -810.67999 | I20: =+SUM(I12:I18) -> -113.00365 | J20: =+SUM(J12:J18) -> -718.439 | K20: =+SUM(K12:K18) -> -903.53515
A23: CASH FLOW ARISING FROM INVESTING ACTIVITIES:
A25: Inflow/ (Outflow) on account of:
A26: Purchase of Fixed Assets | C26: =-SUM('BS '!J45,'BS '!J48)+SUM('BS '!I45,'BS '!I48) -> -7.3697224 | D26: =-SUM('BS '!K45,'BS '!K48)+SUM('BS '!J45,'BS '!J48) -> -36.582889 | E26: =-SUM('BS '!L45,'BS '!L48)+SUM('BS '!K45,'BS '!K48) -> -5 | F26: =-SUM('BS '!M45,'BS '!M48)+SUM('BS '!L45,'BS '!L48) -> -2.5 | G26: =-SUM('BS '!N45,'BS '!N48)+SUM('BS '!M45,'BS '!M48) -> -1.5 | H26: =-SUM('BS '!O45,'BS '!O48)+SUM('BS '!N45,'BS '!N48) -> -5 | I26: =-SUM('BS '!P45,'BS '!P48)+SUM('BS '!O45,'BS '!O48) -> -5.5 | J26: =-SUM('BS '!Q45,'BS '!Q48)+SUM('BS '!P45,'BS '!P48) -> -6 | K26: =-SUM('BS '!R45,'BS '!R48)+SUM('BS '!Q45,'BS '!Q48) -> -6.5
A27: Sale of Fixed Assets
A28: Investment under PTC securities
A29: Net cash flow in cases of Investing Activities(B) | C29: =+SUM(C26:C28) -> -7.3697224 | D29: =+SUM(D26:D28) -> -36.582889 | E29: =+SUM(E26:E28) -> -5 | F29: =+SUM(F26:F28) -> -2.5 | G29: =+SUM(G26:G28) -> -1.5 | H29: =+SUM(H26:H28) -> -5 | I29: =+SUM(I26:I28) -> -5.5 | J29: =+SUM(J26:J28) -> -6 | K29: =+SUM(K26:K28) -> -6.5
A32: CASH FLOW ARISING FROM FINANCING ACTIVITIES
A33: Proceeds from Issue of Share Capital | C33: =SUM('BS '!J12:J13)-SUM('BS '!I12:I13) -> 1.0940358 | D33: =SUM('BS '!K12:K13)-SUM('BS '!J12:J13) -> 0.4357742 | E33: =SUM('BS '!L12:L13)-SUM('BS '!K12:K13) -> 0 | F33: =SUM('BS '!M12:M13)-SUM('BS '!L12:L13) -> 0 | G33: =SUM('BS '!N12:N13)-SUM('BS '!M12:M13) -> 0 | H33: =SUM('BS '!O12:O13)-SUM('BS '!N12:N13) -> 150 | I33: =SUM('BS '!P12:P13)-SUM('BS '!O12:O13) -> 0 | J33: =SUM('BS '!Q12:Q13)-SUM('BS '!P12:P13) -> 0 | K33: =SUM('BS '!R12:R13)-SUM('BS '!Q12:Q13) -> 0
A34: Proceeds from Share Premium | C34: =+'BS '!J16-'BS '!I16 -> 295.55958 | D34: =+'BS '!K16-'BS '!J16 -> 234.56423 | E34: =+'BS '!L16-'BS '!K16 -> 0 | F34: =+'BS '!M16-'BS '!L16 -> 0 | G34: =+'BS '!N16-'BS '!M16 -> 0 | H34: =+'BS '!O16-'BS '!N16 -> 0 | I34: =+'BS '!P16-'BS '!O16 -> 0 | J34: =+'BS '!Q16-'BS '!P16 -> 0 | K34: =+'BS '!R16-'BS '!Q16 -> 0
A35: IND AS Adustment | D35: 10.006185
A36: Share Application Money | C36: 0 | D36: 0 | E36: 0 | F36: 0 | G36: 0 | H36: 0 | I36: 0 | J36: 0 | K36: 0
A37: Unsecured Non Covertiable Debentures | C37: =SUM('BS '!J21,'BS '!J30)-SUM('BS '!I21,'BS '!I30) -> 0 | D37: =SUM('BS '!K21,'BS '!K30)-SUM('BS '!J21,'BS '!J30) -> 0 | E37: =SUM('BS '!L21,'BS '!L30)-SUM('BS '!K21,'BS '!K30) -> 0 | F37: =SUM('BS '!M21,'BS '!M30)-SUM('BS '!L21,'BS '!L30) -> -20 | G37: =SUM('BS '!N21,'BS '!N30)-SUM('BS '!M21,'BS '!M30) -> -20 | H37: =SUM('BS '!O21,'BS '!O30)-SUM('BS '!N21,'BS '!N30) -> 0 | I37: =SUM('BS '!P21,'BS '!P30)-SUM('BS '!O21,'BS '!O30) -> 0 | J37: =SUM('BS '!Q21,'BS '!Q30)-SUM('BS '!P21,'BS '!P30) -> 0 | K37: =SUM('BS '!R21,'BS '!R30)-SUM('BS '!Q21,'BS '!Q30) -> 0
A38: Increase/ ( Decrease) in Unsecured Loans | C38: =+'BS '!J22-'BS '!I22 -> 0 | D38: =+'BS '!K22-'BS '!J22 -> 0 | E38: =+'BS '!L22-'BS '!K22 -> -25 | F38: =+'BS '!M22-'BS '!L22 -> 0 | G38: =+'BS '!N22-'BS '!M22 -> -20 | H38: =+'BS '!O22-'BS '!N22 -> 0 | I38: =+'BS '!P22-'BS '!O22 -> 0 | J38: =+'BS '!Q22-'BS '!P22 -> 0 | K38: =+'BS '!R22-'BS '!Q22 -> 0
A39: Increase in Secured Loans (including Cash Credit) | C39: =+SUM('BS '!J23+'BS '!J27+'BS '!J31+'BS '!J29+'BS '!J32)-('BS '!I23+'BS '!I27+'BS '!I31+'BS '!I29+'BS '!I32) -> 421.4077 | D39: =+SUM('BS '!K23+'BS '!K27+'BS '!K31+'BS '!K29+'BS '!K32)-('BS '!J23+'BS '!J27+'BS '!J31+'BS '!J29+'BS '!J32) -> 1255.6698 | E39: =+SUM('BS '!L23+'BS '!L27+'BS '!L31+'BS '!L29+'BS '!L32)-('BS '!K23+'BS '!K27+'BS '!K31+'BS '!K29+'BS '!K32) -> -1.8878358 | F39: =+SUM('BS '!M23+'BS '!M27+'BS '!M31+'BS '!M29+'BS '!M32)-('BS '!L23+'BS '!L27+'BS '!L31+'BS '!L29+'BS '!L32) -> 377.10217 | G39: =+SUM('BS '!N23+'BS '!N27+'BS '!N31+'BS '!N29+'BS '!N32)-('BS '!M23+'BS '!M27+'BS '!M31+'BS '!M29+'BS '!M32) -> 538.84275 | H39: =+SUM('BS '!O23+'BS '!O27+'BS '!O31+'BS '!O29+'BS '!O32)-('BS '!N23+'BS '!N27+'BS '!N31+'BS '!N29+'BS '!N32) -> 656.19009 | I39: =+SUM('BS '!P23+'BS '!P27+'BS '!P31+'BS '!P29+'BS '!P32)-('BS '!O23+'BS '!O27+'BS '!O31+'BS '!O29+'BS '!O32) -> 222.36073 | J39: =+SUM('BS '!Q23+'BS '!Q27+'BS '!Q31+'BS '!Q29+'BS '!Q32)-('BS '!P23+'BS '!P27+'BS '!P31+'BS '!P29+'BS '!P32) -> 755.60638 | K39: =+SUM('BS '!R23+'BS '!R27+'BS '!R31+'BS '!R29+'BS '!R32)-('BS '!Q23+'BS '!Q27+'BS '!Q31+'BS '!Q29+'BS '!Q32) -> 916.55591
A41: Net Cash flow in cases of Financing Activities (c) | C41: =SUM(C33:C39) -> 718.06132 | D41: =SUM(D33:D39) -> 1500.676 | E41: =SUM(E33:E39) -> -26.887836 | F41: =SUM(F33:F39) -> 357.10217 | G41: =SUM(G33:G39) -> 498.84275 | H41: =SUM(H33:H39) -> 806.19009 | I41: =SUM(I33:I39) -> 222.36073 | J41: =SUM(J33:J39) -> 755.60638 | K41: =SUM(K33:K39) -> 916.55591
A44: Net Increase/(Decrease) in Cash and Cash equivalent (A+B+C) | C44: =+C41+C29+C20 -> 252.27069 | D44: =+D41+D29+D20 -> 140.84274 | E44: =+E41+E29+E20 -> 52.3989 | F44: =+F41+F29+F20 -> -66.570958 | G44: =+G41+G29+G20 -> -38.603594 | H44: =+H41+H29+H20 -> -9.4898947 | I44: =+I41+I29+I20 -> 103.85708 | J44: =+J41+J29+J20 -> 31.167384 | K44: =+K41+K29+K20 -> 6.5207652
A45: Cash and cash equivalent as at the beginning of the year | C45: =+'BS '!I50 -> 9.1876765 | D45: =+'BS '!J50 -> 74.275138 | E45: =+'BS '!K50 -> 62.371605 | F45: =+'BS '!L50 -> 244.25973 | G45: =+'BS '!M50 -> 357.8814 | H45: =+'BS '!N50 -> 324.64497 | I45: =+'BS '!O50 -> 367.44907 | J45: =+'BS '!P50 -> 472.65406 | K45: =+'BS '!Q50 -> 504.49058
A46: Bank deposit not considered as cash or cash equivalent | C46: =-('BS '!J51+'BS '!J52+'BS '!J65+'BS '!J69)+('BS '!I51+'BS '!I52+'BS '!I65+'BS '!I69) -> -187.18485 | D46: =-('BS '!K51+'BS '!K52+'BS '!K65+'BS '!K69)+('BS '!J51+'BS '!J52+'BS '!J65+'BS '!J69) -> -152.74627 | E46: =-('BS '!L51+'BS '!L52+'BS '!L65+'BS '!L69)+('BS '!K51+'BS '!K52+'BS '!K65+'BS '!K69) -> 129.48423 | F46: =-('BS '!M51+'BS '!M52+'BS '!M65+'BS '!M69)+('BS '!L51+'BS '!L52+'BS '!L65+'BS '!L69) -> 180.19837 | G46: =-('BS '!N51+'BS '!N52+'BS '!N65+'BS '!N69)+('BS '!M51+'BS '!M52+'BS '!M65+'BS '!M69) -> 5.3710986 | H46: =-('BS '!O51+'BS '!O52+'BS '!O65+'BS '!O69)+('BS '!N51+'BS '!N52+'BS '!N65+'BS '!N69) -> 52.287618 | I46: =-('BS '!P51+'BS '!P52+'BS '!P65+'BS '!P69)+('BS '!O51+'BS '!O52+'BS '!O65+'BS '!O69) -> 1.3452746 | J46: =-('BS '!Q51+'BS '!Q52+'BS '!Q65+'BS '!Q69)+('BS '!P51+'BS '!P52+'BS '!P65+'BS '!P69) -> 0.67263732 | K46: =-('BS '!R51+'BS '!R52+'BS '!R65+'BS '!R69)+('BS '!Q51+'BS '!Q52+'BS '!Q65+'BS '!Q69) -> 0.33631866
A47: Net cash or cash equivalent as defined in AS-3 | C47: =SUM(C44:C46) -> 74.273521 | D47: =SUM(D44:D46) -> 62.371605 | E47: =SUM(E44:E46) -> 244.25474 | F47: =SUM(F44:F46) -> 357.88714 | G47: =SUM(G44:G46) -> 324.6489 | H47: =SUM(H44:H46) -> 367.44269 | I47: =SUM(I44:I46) -> 472.65142 | J47: =SUM(J44:J46) -> 504.49408 | K47: =SUM(K44:K46) -> 511.34767
C49: ='BS '!J50 -> 74.275138 | D49: ='BS '!K50 -> 62.371605 | E49: ='BS '!L50 -> 244.25973 | F49: ='BS '!M50 -> 357.8814 | G49: ='BS '!N50 -> 324.64497 | H49: ='BS '!O50 -> 367.44907 | I49: ='BS '!P50 -> 472.65406 | J49: ='BS '!Q50 -> 504.49058 | K49: ='BS '!R50 -> 511.3476
C50: =C47-C49 -> -0.0016174282 | D50: =D47-D49 -> -3.1796446e-08 | E50: =E47-E49 -> -0.0049900872 | F50: =F47-F49 -> 0.0057403328 | G50: =G47-G49 -> 0.0039352198 | H50: =H47-H49 -> -0.0063737265 | I50: =I47-I49 -> -0.0026406536 | J50: =J47-J49 -> 0.0034997941 | K50: =K47-K49 -> 6.7620565e-05

Sheet P&L
B1: Ess Kay Fincorp Limited
B2: (Formerly Know as Ess Kay Auto Finance Private Limited)
F3: 10000000 | R3: Rs. in crores
A4: Sr. | B4: Particulars | C4: 2012-13 | D4: 2013-14 | E4: 2014-15 | F4: 2015-16 | G4: 2016-17 | H4: 2017-18 | I4: =Assumptions!B1 -> 2017-18 | J4: =Assumptions!C1 -> 2018-19 | K4: 2019-20 | L4: =Assumptions!E1 -> 2020-21 | M4: =Assumptions!F1 -> 2021-22 | N4: =Assumptions!G1 -> 2022-23 | O4: =Assumptions!H1 -> 2023-24 | P4: =Assumptions!I1 -> 2024-25 | Q4: =Assumptions!J1 -> 2025-26 | R4: =Assumptions!K1 -> 2026-27
C5: Audited | D5: Audited | E5: Audited | F5: Audited | G5: Audited | H5: 43100 | I5: =Assumptions!B2 -> Audited | J5: =Assumptions!C2 -> Audited | K5: Audited | L5: =Assumptions!E2 -> Projected | M5: =Assumptions!F2 -> Projected | N5: =Assumptions!G2 -> Projected | O5: =Assumptions!H2 -> Projected | P5: =Assumptions!I2 -> Projected | Q5: =Assumptions!J2 -> Projected | R5: =Assumptions!K2 -> Projected
A6: A | B6: Income:
A7: 1 | B7: Interest on own books | C7: 27.941476 | D7: 52.88184 | E7: 69.85693 | F7: 91.444452 | G7: 117.76431 | H7: 117.92298 | I7: 165.60983 | J7: 286.46203 | K7: 501.9266 | L7: 570.51911 | M7: 649.91917 | N7: 766.8167 | O7: 934.95588 | P7: 1057.84 | Q7: 1193.4371 | R7: 1414.4281
A8: =A7+1 -> 2 | B8: Income on other loans/ FDRs | C8: 2.4072938 | D8: 2.9419794 | E8: 2.9788142 | F8: 2.5868937 | G8: 2.8003227 | H8: 2.9977927 | I8: 3.6963189 | J8: 7.3399014 | K8: 24.6196 | L8: 1.166965 | M8: 0.89468042 | N8: 0.55084767 | O8: 0.28851912 | P8: 0.15735484 | Q8: 0.0917727 | R8: 0.05898163
A9: =A8+1 -> 3 | B9: Income from securitisation | C9: 3.0393434 | D9: 2.7533424 | E9: 6.1872521 | F9: 8.4392732 | G9: 15.915354 | H9: 19.301367 | I9: 31.229409 | J9: 25.942072 | K9: 18.8988 | L9: 25.627159 | M9: 35.117549 | N9: 44.066128 | O9: 48.241515 | P9: 54.988724 | Q9: 74.955222 | R9: 94.807331
A10: =A9+1 -> 4 | B10: Income on closer | C10: 0.4029941 | D10: 0.3289521 | E10: 0.7492187 | F10: 0.6503935 | G10: 1.6948201 | H10: 0.9337919 | I10: 1.4594912 | J10: 3.8804455 | K10: 7.564 | L10: 9.5651367 | M10: 10.042075 | N10: 11.036501 | O10: 13.355323 | P10: 15.342539 | Q10: 17.555247 | R10: 20.919748
A11: =A10+1 -> 5 | B11: Processing Charges | C11: 4.1205341 | D11: 5.3058855 | E11: 6.1198 | F11: 8.0566426 | G11: 13.492248 | H11: 16.143196 | I11: 23.99948 | J11: 36.937927 | K11: 19.5152 | L11: 15.625 | M11: 20.6 | N11: 24.7 | O11: 29.6 | P11: 35.5 | Q11: 42.6 | R11: 51.1
A12: =A11+1 -> 6 | B12: Insurance division income | C12: 2.059023 | D12: 2.0641043 | E12: 2.7216233 | F12: 4.6072382 | G12: 5.5390277 | H12: 1.57834 | I12: 1.3354 | J12: 4.3722219 | K12: 9.8785 | L12: 2.2321429 | M12: 3.6785714 | N12: 4.4107143 | O12: 5.2857143 | P12: 6.3392857 | Q12: 7.6071429 | R12: 9.125
B14: Total | C14: =ROUND(SUM(C7:C13),2) -> 39.97 | D14: =ROUND(SUM(D7:D13),2) -> 66.28 | E14: =ROUND(SUM(E7:E13),2) -> 88.61 | F14: =(SUM(F7:F13)) -> 115.78489 | G14: =(SUM(G7:G13)) -> 157.20608 | H14: 158.87747 | I14: =(SUM(I7:I13)) -> 227.32993 | J14: =(SUM(J7:J13)) -> 364.9346 | K14: =(SUM(K7:K13)) -> 582.4027 | L14: =(SUM(L7:L13)) -> 624.73551 | M14: =(SUM(M7:M13)) -> 720.25205 | N14: =(SUM(N7:N13)) -> 851.58089 | O14: =(SUM(O7:O13)) -> 1031.7269 | P14: =(SUM(P7:P13)) -> 1170.1679 | ... R14: =(SUM(R7:R13)) -> 1590.4392
A15: B | B15: Expenses:
A16: 1 | B16: Employee Remuneration & Benefits | C16: 5.2990314 | D16: 7.1521719 | E16: 10.365872 | F16: 17.954191 | G16: 31.671286 | H16: 34.949398 | I16: 50.020488 | J16: 70.844841 | K16: 105.7101 | L16: 112.04311 | M16: 124.51132 | N16: 140.07523 | O16: 162.58464 | P16: 175.40771 | Q16: 190.33368 | R16: 221.12539
A17: 2 | B17: Admin & Other Expenses | C17: 11.835023 | D17: 15.080604 | E17: 19.08034 | F17: 25.599427 | G17: 30.344664 | H17: 29.436418 | I17: 38.835668 | J17: 55.277349 | K17: =40.5483+11.33671532 -> 51.885015 | L17: 56.876335 | M17: 63.838986 | N17: 74.308825 | O17: 89.7245 | P17: 98.56678 | Q17: 109.126 | R17: 125.40118
A18: 3 | B18: Interest Cost | C18: 10.277614 | D18: 28.274786 | E18: 39.86591 | F18: 47.494884 | G18: 65.699066 | H18: 62.451363 | I18: 84.786533 | J18: 130.96283 | K18: 222.5017 | L18: 227.6924 | M18: 263.89367 | N18: 322.28782 | O18: 382.78033 | P18: 435.77059 | Q18: 492.96369 | R18: 586.54249
A19: 4 | B19: Other Financial Cost | C19: 0.5588341 | D19: 1.5617603 | E19: 0.8631912 | F19: 0.91951 | G19: 3.4562711 | H19: 2.7762855 | I19: 4.6641167 | J19: 7.4993406 | K19: 9.9828 | L19: 10.64 | M19: 12.48 | N19: 14.7 | O19: 16.8 | P19: 18.96 | Q19: 21.266 | R19: 21.515
B21: Total | C21: =ROUND(SUM(C16:C20),2) -> 27.97 | D21: =ROUND(SUM(D16:D20),2) -> 52.07 | E21: =ROUND(SUM(E16:E20),2) -> 70.18 | F21: =(SUM(F16:F20)) -> 91.968012 | G21: =(SUM(G16:G20)) -> 131.17129 | H21: 129.61346 | I21: =(SUM(I16:I20)) -> 178.30681 | J21: =(SUM(J16:J20)) -> 264.58436 | K21: =(SUM(K16:K20)) -> 390.07962 | L21: =(SUM(L16:L20)) -> 407.25184 | M21: =(SUM(M16:M20)) -> 464.72398 | N21: =(SUM(N16:N20)) -> 551.37188 | O21: =(SUM(O16:O20)) -> 651.88947 | P21: =(SUM(P16:P20)) -> 728.70509 | ... R21: =(SUM(R16:R20)) -> 954.58406
J22: =($I22/(+$I$22+$I$33+$I$34+$I$37))*((+$I$22+$I$33+$I$34+$I$37)+SUM('P&L'!$J$26:J26)) -> 0 | L22: =($I22/(+$I$22+$I$33+$I$34+$I$37))*((+$I$22+$I$33+$I$34+$I$37)+SUM('P&L'!$J$26:L26)) -> 0 | M22: =($I22/(+$I$22+$I$33+$I$34+$I$37))*((+$I$22+$I$33+$I$34+$I$37)+SUM('P&L'!$J$26:M26)) -> 0 | N22: =($I22/(+$I$22+$I$33+$I$34+$I$37))*((+$I$22+$I$33+$I$34+$I$37)+SUM('P&L'!$J$26:N26)) -> 0 | O22: =($I22/(+$I$22+$I$33+$I$34+$I$37))*((+$I$22+$I$33+$I$34+$I$37)+SUM('P&L'!$J$26:O26)) -> 0 | P22: =($I22/(+$I$22+$I$33+$I$34+$I$37))*((+$I$22+$I$33+$I$34+$I$37)+SUM('P&L'!$J$26:P26)) -> 0 | Q22: =($I22/(+$I$22+$I$33+$I$34+$I$37))*((+$I$22+$I$33+$I$34+$I$37)+SUM('P&L'!$J$26:Q26)) -> 0 | R22: =($I22/(+$I$22+$I$33+$I$34+$I$37))*((+$I$22+$I$33+$I$34+$I$37)+SUM('P&L'!$J$26:R26)) -> 0
A23: C | B23: Operating Income | C23: =ROUND(C14-C21,2) -> 12 | D23: =ROUND(D14-D21,2) -> 14.21 | E23: =ROUND(E14-E21,2) -> 18.43 | F23: =F14-F21 -> 23.816881 | G23: =G14-G21 -> 26.034797 | H23: 29.264006 | I23: =I14-I21 -> 49.023127 | J23: =J14-J21 -> 100.35024 | K23: =K14-K21 -> 192.32308 | L23: =L14-L21 -> 217.48367 | M23: =M14-M21 -> 255.52807 | N23: =N14-N21 -> 300.20901 | O23: =O14-O21 -> 379.83748 | P23: =P14-P21 -> 441.46278 | ... R23: =R14-R21 -> 635.85512
A24: 1 | B24: Depreciation | C24: 0.2747612 | D24: 0.3271916 | E24: 0.7303756 | F24: 0.86844253 | G24: 1.6132389 | H24: 1.668903 | I24: 2.3362425 | J24: 3.2124975 | K24: 8.1753 | L24: ='BS '!L46-'BS '!K46 -> 8.2855814 | M24: ='BS '!M46-'BS '!L46 -> 8.6105814 | N24: ='BS '!N46-'BS '!M46 -> 9.1955814 | O24: ='BS '!O46-'BS '!N46 -> 9.8455814 | P24: ='BS '!P46-'BS '!O46 -> 10.560581 | Q24: ='BS '!Q46-'BS '!P46 -> 11.340581 | R24: ='BS '!R46-'BS '!Q46 -> 12.185581
A25: 2 | B25: Loss on sale of fixed assets/shares | C25: 0 | D25: 0 | E25: 0 | F25: 0 | G25: 0 | J25: 0 | L25: 0 | M25: 0 | N25: 0 | O25: 0 | P25: 0 | Q25: 0 | R25: 0
A26: 3 | B26: Provisions | C26: 0.4371177 | D26: 0.15762298 | E26: 1.4829147 | F26: 1.1384812 | G26: 3.8657067 | H26: 11.126832 | I26: 6.6369022 | J26: 8.8024388 | K26: =5508.4/100 -> 55.084 | L26: 49.997763 | M26: 36.57622 | N26: 25.655168 | O26: 34.929884 | P26: 20.567563 | Q26: 27.506933 | R26: 34.284947
A27: 4 | B27: Writeoffs /OTS/Repo loss | C27: 0.6024051 | D27: 1.4530741 | E27: 2.4781955 | F27: 3.2217362 | G27: 1.7335833 | H27: 2.7848642 | I27: 7.1254787 | J27: 12.84427 | K27: 23.5591 | L27: 38.972459 | M27: 37.234577 | N27: 44.559204 | O27: 55.169423 | P27: 59.78357 | Q27: 68.082861 | R27: 81.005509
A28: 5 | B28: Misc. exp. Written off | C28: 0 | D28: 0 | E28: 0 | F28: 0 | G28: 0 | I28: 0 | J28: 0 | L28: 0 | M28: 0 | N28: 0 | O28: 0 | P28: 0 | Q28: 0 | R28: 0
A29: 6 | B29: Prior period expenses | C29: 0 | D29: 0 | E29: 0 | F29: 0 | G29: 0 | I29: 0 | J29: 0 | L29: 0 | M29: 0 | N29: 0 | O29: 0 | P29: 0 | Q29: 0 | R29: 0
A30: D | B30: PBT | C30: =ROUND(C23-SUM(C24:C29),2) -> 10.69 | D30: =ROUND(D23-SUM(D24:D29),2) -> 12.27 | E30: =ROUND(E23-SUM(E24:E29),2) -> 13.74 | F30: =(F23-SUM(F24:F29)) -> 18.588221 | G30: =(G23-SUM(G24:G29)) -> 18.822268 | H30: 13.683407 | I30: =(I23-SUM(I24:I29)) -> 32.924504 | J30: =(J23-SUM(J24:J29)) -> 75.491033 | K30: =(K23-SUM(K24:K29)) -> 105.50468 | L30: =(L23-SUM(L24:L29)) -> 120.22786 | M30: =(M23-SUM(M24:M29)) -> 173.1067 | N30: =(N23-SUM(N24:N29)) -> 220.79906 | O30: =(O23-SUM(O24:O29)) -> 279.89259 | P30: =(P23-SUM(P24:P29)) -> 350.55106 | ... R30: =(R23-SUM(R24:R29)) -> 508.37908
A31: 1 | B31: Direct Income Tax | C31: 3.6366098 | D31: 4.4701247 | E31: 5.2904646 | F31: 7.1644577 | G31: 9.0811972 | H31: 6.3914086 | I31: 12.881457 | J31: 26.255704 | K31: 38.7432 | L31: =L30*25.17% -> 30.261353 | M31: =M30*25.17% -> 43.570955 | N31: =N30*25.17% -> 55.575123 | O31: =O30*25.17% -> 70.448965 | P31: =P30*25.17% -> 88.233702 | Q31: =Q30*25.17% -> 104.61325 | R31: =R30*25.17% -> 127.95902
A32: 2 | B32: Deferred Income Tax | C32: -0.1350407 | D32: -0.2044179 | E32: -0.5886533 | F32: -0.5871484 | G32: -2.5574891 | H32: -2.7431571 | I32: -1.9091848 | J32: -2.994868 | K32: -11.7752 | L32: 0 | M32: 0 | N32: 0 | O32: 0 | P32: 0 | Q32: 0 | R32: 0
A33: 3 | B33: Fringe Benefit Tax/PY Income tax | C33: 0 | D33: 0 | E33: 0 | F33: 0 | G33: 0 | J33: =($I33/(+$I$22+$I$33+$I$34+$I$37))*((+$I$22+$I$33+$I$34+$I$37)+SUM('P&L'!$J$26:J26)) -> 0 | L33: =($I33/(+$I$22+$I$33+$I$34+$I$37))*((+$I$22+$I$33+$I$34+$I$37)+SUM('P&L'!$J$26:L26)) -> 0 | M33: =($I33/(+$I$22+$I$33+$I$34+$I$37))*((+$I$22+$I$33+$I$34+$I$37)+SUM('P&L'!$J$26:M26)) -> 0 | N33: =($I33/(+$I$22+$I$33+$I$34+$I$37))*((+$I$22+$I$33+$I$34+$I$37)+SUM('P&L'!$J$26:N26)) -> 0 | O33: =($I33/(+$I$22+$I$33+$I$34+$I$37))*((+$I$22+$I$33+$I$34+$I$37)+SUM('P&L'!$J$26:O26)) -> 0 | P33: =($I33/(+$I$22+$I$33+$I$34+$I$37))*((+$I$22+$I$33+$I$34+$I$37)+SUM('P&L'!$J$26:P26)) -> 0 | Q33: =($I33/(+$I$22+$I$33+$I$34+$I$37))*((+$I$22+$I$33+$I$34+$I$37)+SUM('P&L'!$J$26:Q26)) -> 0 | R33: =($I33/(+$I$22+$I$33+$I$34+$I$37))*((+$I$22+$I$33+$I$34+$I$37)+SUM('P&L'!$J$26:R26)) -> 0
A34: E | B34: PAT | C34: =ROUND(C30-C31-C32-C33,2) -> 7.19 | D34: =ROUND(D30-D31-D32-D33,2) -> 8 | E34: =ROUND(E30-E31-E32-E33,2) -> 9.04 | F34: =(F30-F31-F32-F33) -> 12.010912 | G34: =(G30-G31-G32-G33) -> 12.29856 | H34: 10.035155 | I34: =(I30-I31-I32-I33) -> 21.952231 | J34: =(J30-J31-J32-J33) -> 52.230197 | K34: =(K30-K31-K32-K33) -> 78.536684 | L34: =(L30-L31-L32-L33) -> 89.96651 | M34: =(M30-M31-M32-M33) -> 129.53574 | N34: =(N30-N31-N32-N33) -> 165.22394 | O34: =(O30-O31-O32-O33) -> 209.44363 | P34: =(P30-P31-P32-P33) -> 262.31736 | ... R34: =(R30-R31-R32-R33) -> 380.42007
A35: 1 | B35: Dividend | C35: 0 | D35: 0 | E35: 0 | F35: 0 | G35: 0 | I35: 0 | J35: 0 | L35: 0 | M35: 0 | N35: 0 | O35: 0 | P35: 0 | Q35: 0 | R35: 0
A36: F | B36: Retained Profit | C36: =C34-C35 -> 7.19 | D36: =D34-D35 -> 8 | E36: =E34-E35 -> 9.04 | F36: =F34-F35 -> 12.010912 | G36: =G34-G35 -> 12.29856 | H36: 10.035155 | I36: =I34-I35 -> 21.952231 | J36: =J34-J35 -> 52.230197 | K36: =K34-K35 -> 78.536684 | L36: =L34-L35 -> 89.96651 | M36: =M34-M35 -> 129.53574 | N36: =N34-N35 -> 165.22394 | O36: =O34-O35 -> 209.44363 | P36: =P34-P35 -> 262.31736 | ... R36: =R34-R35 -> 380.42007
A37: G | B37: Cash Accruals | C37: =C34+C28+C26+C24 -> 7.9018789 | D37: =D34+D28+D26+D24 -> 8.4848146 | E37: =E34+E28+E26+E24 -> 11.25329 | F37: =F34+F28+F26+F24 -> 14.017835 | G37: =G34+G28+G26+G24 -> 17.777506 | H37: 22.83089 | I37: =I34+I28+I26+I24 -> 30.925376 | J37: =J34+J28+J26+J24 -> 64.245134 | K37: =K34+K28+K26+K24 -> 141.79598 | L37: =L34+L28+L26+L24 -> 148.24985 | M37: =M34+M28+M26+M24 -> 174.72254 | N37: =N34+N28+N26+N24 -> 200.07468 | O37: =O34+O28+O26+O24 -> 254.21909 | P37: =P34+P28+P26+P24 -> 293.4455 | ... R37: =R34+R28+R26+R24 -> 426.8906

Sheet DSCR
B3: Ess Kay Fincorp Private Limited
B4: (Formerly Known as Ess Kay Auto Finance Limited)
B7: Calculation of DSCR | J7: (Rs in Crore)
B8: Particulars | C8: 2019-20 | D8: ='BS '!L7 -> 2020-21 | E8: ='BS '!M7 -> 2021-22 | F8: ='BS '!N7 -> 2022-23 | G8: ='BS '!O7 -> 2023-24 | H8: ='BS '!P7 -> 2024-25 | I8: ='BS '!Q7 -> 2025-26 | J8: ='BS '!R7 -> 2026-27
C9: Audited | D9: ='BS '!L8 -> Projected | E9: ='BS '!M8 -> Projected | F9: ='BS '!N8 -> Projected | G9: ='BS '!O8 -> Projected | H9: ='BS '!P8 -> Projected | I9: ='BS '!Q8 -> Projected | J9: ='BS '!R8 -> Projected
B10: Cash Profit | C10: =C28 -> 141.79598 | D10: =D28 -> 148.24985 | E10: =E28 -> 174.72254 | F10: =F28 -> 200.07468 | G10: =G28 -> 254.21909 | H10: =H28 -> 293.4455 | I10: =I28 -> 349.86101 | J10: =J28 -> 426.8906
B11: Add: Collection received | C11: =C36 -> 1004.8171 | D11: =D36 -> 950.53206 | E11: =E36 -> 1244.339 | F11: =F36 -> 1487.5373 | G11: =G36 -> 1748.9781 | H11: =H36 -> 2787.7769 | I11: =I36 -> 2766.3079 | J11: =J36 -> 3274.6001
B12: Add: Existing Liquidity Buffer | C12: 325.52034 | D12: ='BS '!L50+'BS '!L58+'BS '!L69 -> 469.25973 | E12: ='BS '!M50+'BS '!M58+'BS '!M69 -> 407.8814 | F12: ='BS '!N50+'BS '!N58+'BS '!N69 -> 374.64497 | G12: ='BS '!O50+'BS '!O58+'BS '!O69 -> 367.852 | H12: ='BS '!P50+'BS '!P58+'BS '!P69 -> 473.05699 | I12: ='BS '!Q50+'BS '!Q58+'BS '!Q69 -> 504.89351 | J12: ='BS '!R50+'BS '!R58+'BS '!R69 -> 511.75053
B13: Add: Interest on Term Loan & Tier II Capital | C13: =C38 -> 222.5017 | D13: =D38 -> 227.6924 | E13: =E38 -> 263.89367 | F13: =F38 -> 322.28782 | G13: =G38 -> 382.78033 | H13: =H38 -> 435.77059 | I13: =I38 -> 492.96369 | J13: =J38 -> 586.54249
B14: Add: Fresh Equity Infusion | C14: =Assumptions!D59 -> 235 | D14: =Assumptions!E59 -> 0 | E14: =Assumptions!F59 -> 0 | F14: =Assumptions!G59 -> 0 | G14: =Assumptions!H59 -> 150 | H14: =Assumptions!I59 -> 0 | I14: =Assumptions!J59 -> 0 | J14: =Assumptions!K59 -> 0
B15: Total Cash accruals (A) | C15: =SUM(C10:C14) -> 1929.6352 | D15: =SUM(D10:D14) -> 1795.734 | E15: =SUM(E10:E14) -> 2090.8366 | F15: =SUM(F10:F14) -> 2384.5448 | G15: =SUM(G10:G14) -> 2903.8295 | H15: =SUM(H10:H14) -> 3990.05 | I15: =SUM(I10:I14) -> 4114.0261 | J15: =SUM(J10:J14) -> 4799.7837
B17: Repayment of TL | C17: =C40 -> 801.67813 | D17: =D40 -> 1036.1027 | E17: =E40 -> 845.58871 | F17: =F40 -> 854.11722 | G17: =G40 -> 1197.0659 | H17: =H40 -> 1731.2208 | I17: =I40 -> 2048.3333 | J17: =J40 -> 2087.7778
B18: Payment of Interest | C18: =C13 -> 222.5017 | D18: =D13 -> 227.6924 | E18: =E13 -> 263.89367 | F18: =F13 -> 322.28782 | G18: =G13 -> 382.78033 | H18: =H13 -> 435.77059 | I18: =I13 -> 492.96369 | J18: =J13 -> 586.54249
B19: Total Repayment Obligation (B) | C19: =SUM(C17:C18) -> 1024.1798 | D19: =SUM(D17:D18) -> 1263.7951 | E19: =SUM(E17:E18) -> 1109.4824 | F19: =SUM(F17:F18) -> 1176.405 | G19: =SUM(G17:G18) -> 1579.8462 | H19: =SUM(H17:H18) -> 2166.9914 | I19: =SUM(I17:I18) -> 2541.297 | J19: =SUM(J17:J18) -> 2674.3203
B21: DSCR (A/B) | C21: =C15/C19 -> 1.8840785 | D21: =D15/D19 -> 1.420906 | E21: =E15/E19 -> 1.8845154 | F21: =F15/F19 -> 2.026976 | G21: =G15/G19 -> 1.8380457 | H21: =H15/H19 -> 1.8412856 | I21: =I15/I19 -> 1.6188687 | J21: =J15/J19 -> 1.7947677
B22: Average DSCR | C22: =SUM(D15:J15)/SUM(D19:J19) -> 1.764591
B24: Caculation of cash Profit
B25: PAT | C25: ='P&L'!K34 -> 78.536684 | D25: ='P&L'!L34 -> 89.96651 | E25: ='P&L'!M34 -> 129.53574 | F25: ='P&L'!N34 -> 165.22394 | G25: ='P&L'!O34 -> 209.44363 | H25: ='P&L'!P34 -> 262.31736 | I25: ='P&L'!Q34 -> 311.0135 | J25: ='P&L'!R34 -> 380.42007
B26: Add: Depriciation | C26: ='P&L'!K24 -> 8.1753 | D26: ='P&L'!L24 -> 8.2855814 | E26: ='P&L'!M24 -> 8.6105814 | F26: ='P&L'!N24 -> 9.1955814 | G26: ='P&L'!O24 -> 9.8455814 | H26: ='P&L'!P24 -> 10.560581 | I26: ='P&L'!Q24 -> 11.340581 | J26: ='P&L'!R24 -> 12.185581
B27: Add: Provisions | C27: ='P&L'!K26 -> 55.084 | D27: ='P&L'!L26 -> 49.997763 | E27: ='P&L'!M26 -> 36.57622 | F27: ='P&L'!N26 -> 25.655168 | G27: ='P&L'!O26 -> 34.929884 | H27: ='P&L'!P26 -> 20.567563 | I27: ='P&L'!Q26 -> 27.506933 | J27: ='P&L'!R26 -> 34.284947
B28: Cash Profit | C28: =SUM(C25:C27) -> 141.79598 | D28: =SUM(D25:D27) -> 148.24985 | E28: =SUM(E25:E27) -> 174.72254 | F28: =SUM(F25:F27) -> 200.07468 | G28: =SUM(G25:G27) -> 254.21909 | H28: =SUM(H25:H27) -> 293.4455 | I28: =SUM(I25:I27) -> 349.86101 | J28: =SUM(J25:J27) -> 426.8906
B30: Calculation of Collection Received
B31: Opening POS | C31: 1807.8159 | D31: =C35 -> 2948.3288 | E31: =D35 -> 3117.7967 | F31: =E35 -> 3723.4577 | G31: =F35 -> 4455.9204 | H31: =G35 -> 5516.9423 | I31: =H35 -> 5919.1654 | J31: =I35 -> 6982.8575
B32: Add: Disbursement | C32: 2193.46 | D32: 1250 | E32: 2060 | F32: 2470 | G32: 2960 | H32: 3550 | I32: 4260 | J32: 5110
B34: Less: Securitized POS | C34: 48.13 | D34: 130 | E34: 210 | F34: 250 | G34: 150 | H34: 360 | I34: 430 | J34: 510
B35: Less: Closing POS own books | C35: =SUM('BS '!K54,'BS '!K61,'BS '!K66) -> 2948.3288 | D35: =SUM('BS '!L54,'BS '!L61,'BS '!L66) -> 3117.7967 | E35: =SUM('BS '!M54,'BS '!M61,'BS '!M66) -> 3723.4577 | F35: =SUM('BS '!N54,'BS '!N61,'BS '!N66) -> 4455.9204 | G35: =SUM('BS '!O54,'BS '!O61,'BS '!O66) -> 5516.9423 | H35: =SUM('BS '!P54,'BS '!P61,'BS '!P66) -> 5919.1654 | I35: =SUM('BS '!Q54,'BS '!Q61,'BS '!Q66) -> 6982.8575 | J35: =SUM('BS '!R54,'BS '!R61,'BS '!R66) -> 8308.2574
B36: Collection from customers | C36: =C31+C32-C34-C35+C33 -> 1004.8171 | D36: =D31+D32-D34-D35+D33 -> 950.53206 | E36: =E31+E32-E34-E35+E33 -> 1244.339 | F36: =F31+F32-F34-F35+F33 -> 1487.5373 | G36: =G31+G32-G34-G35+G33 -> 1748.9781 | H36: =H31+H32-H34-H35+H33 -> 2787.7769 | I36: =I31+I32-I34-I35+I33 -> 2766.3079 | J36: =J31+J32-J34-J35+J33 -> 3274.6001
B38: Calculation of Interest paid on Term Loan & Tier II capital | C38: ='P&L'!K18 -> 222.5017 | D38: =SUM('P&L'!L18) -> 227.6924 | E38: =SUM('P&L'!M18) -> 263.89367 | F38: =SUM('P&L'!N18) -> 322.28782 | G38: =SUM('P&L'!O18) -> 382.78033 | H38: =SUM('P&L'!P18) -> 435.77059 | I38: =SUM('P&L'!Q18) -> 492.96369 | J38: =SUM('P&L'!R18) -> 586.54249
B40: Repayment of TL | C40: 801.67813 | D40: 1036.1027 | E40: 845.58871 | F40: 854.11722 | G40: 1197.0659 | H40: 1731.2208 | I40: 2048.3333 | J40: 2087.7778
